<mujoco model="spirit">
  <compiler angle="radian" autolimits="true" coordinate="local"/>
  
  <default>
    <motor ctrlrange="-33.5 33.5" ctrllimited="true"/>
    <joint damping="0.01" armature="0.01" frictionloss="0.2" />
  </default>
  
  <asset>
    <texture builtin="gradient" height="100" rgb1="1 1 1" rgb2="0 0 0" type="skybox" width="100"/>
    <texture builtin="flat" height="1278" mark="cross" markrgb="1 1 1" name="texgeom" random="0.01" rgb1="0.8 0.6 0.4" rgb2="0.8 0.6 0.4" type="cube" width="127"/>
    <texture builtin="checker" height="100" name="texplane" rgb1="0 0 0" rgb2="0.8 0.8 0.8" type="2d" width="100"/>
    <material name="MatPlane" reflectance="0.5" shininess="1" specular="1" texrepeat="60 60" texture="texplane"/>
    <material name="geom" texture="texgeom" texuniform="true"/>
  </asset>
  
  <worldbody>
    <light cutoff="100" diffuse="1 1 1" dir="-0 0 -1.3" directional="true" exponent="1" pos="0 0 1.3" specular=".1 .1 .1"/>
    <geom conaffinity="1" condim="3" material="MatPlane" name="floor" pos="0 0 0" size="40 40 40" type="plane"/>
    <body name="body" pos="0.0 0.0 0.6">
      <camera name="track" mode="trackcom" pos="0 -3 0.3" xyaxes="1 0 0 0 0 1"/>
      <geom size="0.1675 0.12 0.052" type="box" rgba="0.1 0.1 0.1 1"/>
      <joint armature="0" damping="0" limited="false" margin="0.01" name="root" pos="0 0 0" type="free"/>
      <body name="hip0" pos="0.2263 0.07 0" gravcomp="0">
        <inertial pos="0 0 0" quat="0.5 0.5 -0.5 0.5" mass="0.575" diaginertia="0.000869688 0.000669635 0.000669635"/>
        <joint name="8" pos="0 0 0" axis="1 0 0" range="-0.707 0.707"/>
        <geom size="0.055 0.04" pos="0 0.028 0" quat="0.707107 0.707107 0 0" type="cylinder" rgba="0.1 0.1 0.1 1"/>
        <body name="upper0" pos="0 0.10098 0" gravcomp="0">
          <inertial pos="0 0 0" quat="0.5 0.5 0.5 0.5" mass="0.775" diaginertia="0.001 0.001 5e-05"/>
          <joint name="0" pos="0 0 0" axis="0 -1 0" range="-6.28319 6.28319"/>
          <geom size="0.103 0.011 0.0275" pos="-0.103 -0.022 0" type="box" rgba="0.3 0.3 0.3 1"/>
          <body name="lower0" pos="-0.206 0 0" gravcomp="0">
            <inertial pos="0.0343333 0 0" quat="0.5 0.5 0.5 0.5" mass="0.09" diaginertia="0.00065545 0.00065545 3e-05"/>
            <joint name="1" pos="0 0 0" axis="0 1 0" range="0 3.14159"/>
            <geom size="0.013 0.103" pos="0.103 0 0" quat="0.707107 0 0.707107 0" type="cylinder" rgba="0.1 0.1 0.1 1"/>
            <geom size="0.02" pos="0.206 0 0" rgba="0.1 0.1 0.1 1"/>
          </body>
        </body>
      </body>

      <body name="hip1" pos="-0.2263 0.07 0" gravcomp="0">
        <inertial pos="0 0 0" quat="0.5 0.5 -0.5 0.5" mass="0.575" diaginertia="0.000869688 0.000669635 0.000669635"/>
        <joint name="9" pos="0 0 0" axis="1 0 0" range="-0.707 0.707"/>
        <geom size="0.055 0.04" pos="0 0.028 0" quat="0.707107 0.707107 0 0" type="cylinder" rgba="0.1 0.1 0.1 1"/>
        <body name="upper1" pos="0 0.10098 0" gravcomp="0">
          <inertial pos="0 0 0" quat="0.5 0.5 0.5 0.5" mass="0.775" diaginertia="0.001 0.001 5e-05"/>
          <joint name="2" pos="0 0 0" axis="0 -1 0" range="-6.28319 6.28319"/>
          <geom size="0.103 0.011 0.0275" pos="-0.103 -0.022 0" type="box" rgba="0.3 0.3 0.3 1"/>
          <body name="lower1" pos="-0.206 0 0" gravcomp="0">
            <inertial pos="0.0343333 0 0" quat="0.5 0.5 0.5 0.5" mass="0.09" diaginertia="0.00065545 0.00065545 3e-05"/>
            <joint name="3" pos="0 0 0" axis="0 1 0" range="0 3.14159"/>
            <geom size="0.013 0.103" pos="0.103 0 0" quat="0.707107 0 0.707107 0" type="cylinder" rgba="0.1 0.1 0.1 1"/>
            <geom size="0.02" pos="0.206 0 0" rgba="0.1 0.1 0.1 1"/>
          </body>
        </body>
      </body>

      <body name="hip2" pos="0.2263 -0.07 0" gravcomp="0">
        <inertial pos="0 0 0" quat="0.5 0.5 -0.5 0.5" mass="0.575" diaginertia="0.000869688 0.000669635 0.000669635"/>
        <joint name="10" pos="0 0 0" axis="1 0 0" range="-0.707 0.707"/>
        <geom size="0.055 0.04" pos="0 -0.028 0" quat="0.707107 0.707107 0 0" type="cylinder" rgba="0.8 0 0.2 1"/>
        <body name="upper2" pos="0 -0.10098 0" gravcomp="0">
          <inertial pos="0 0 0" quat="0.5 0.5 0.5 0.5" mass="0.775" diaginertia="0.001 0.001 5e-05"/>
          <joint name="4" pos="0 0 0" axis="0 -1 0" range="-6.28319 6.28319"/>
          <geom size="0.103 0.011 0.0275" pos="-0.103 0.022 0" type="box" rgba="0.3 0.3 0.3 1"/>
          <body name="lower2" pos="-0.206 0 0" gravcomp="0">
            <inertial pos="0.0343333 0 0" quat="0.5 0.5 0.5 0.5" mass="0.09" diaginertia="0.00065545 0.00065545 3e-05"/>
            <joint name="5" pos="0 0 0" axis="0 1 0" range="0 3.14159"/>
            <geom size="0.013 0.103" pos="0.103 0 0" quat="0.707107 0 0.707107 0" type="cylinder" rgba="0.1 0.1 0.1 1"/>
            <geom size="0.02" pos="0.206 0 0" rgba="0.1 0.1 0.1 1"/>
          </body>
        </body>
      </body>

      <body name="hip3" pos="-0.2263 -0.07 0" gravcomp="0">
        <inertial pos="0 0 0" quat="0.5 0.5 -0.5 0.5" mass="0.575" diaginertia="0.000869688 0.000669635 0.000669635"/>
        <joint name="11" pos="0 0 0" axis="1 0 0" range="-0.707 0.707"/>
        <geom size="0.055 0.04" pos="0 -0.028 0" quat="0.707107 0.707107 0 0" type="cylinder" rgba="0.1 0.1 0.1 1"/>
        <body name="upper3" pos="0 -0.10098 0" gravcomp="0">
          <inertial pos="0 0 0" quat="0.5 0.5 0.5 0.5" mass="0.775" diaginertia="0.001 0.001 5e-05"/>
          <joint name="6" pos="0 0 0" axis="0 -1 0" range="-6.28319 6.28319"/>
          <geom size="0.103 0.011 0.0275" pos="-0.103 0.022 0" type="box" rgba="0.3 0.3 0.3 1"/>
          <body name="lower3" pos="-0.206 0 0" gravcomp="0">
            <inertial pos="0.0343333 0 0" quat="0.5 0.5 0.5 0.5" mass="0.09" diaginertia="0.00065545 0.00065545 3e-05"/>
            <joint name="7" pos="0 0 0" axis="0 1 0" range="0 3.14159"/>
            <geom size="0.013 0.103" pos="0.103 0 0" quat="0.707107 0 0.707107 0" type="cylinder" rgba="0.1 0.1 0.1 1"/>
            <geom size="0.02" pos="0.206 0 0" rgba="0.1 0.1 0.1 1"/>
          </body>
        </body>
      </body>
    </body>
  </worldbody>
  <actuator>
    <motor joint="8" gear="1"/>
    <motor joint="0" gear="1"/>
    <motor joint="1" gear="1"/>
    
    <motor joint="9" gear="1"/>
    <motor joint="2" gear="1"/>
    <motor joint="3" gear="1"/>

    <motor joint="10" gear="1"/>
    <motor joint="4" gear="1"/>
    <motor joint="5" gear="1"/>

    <motor joint="11" gear="1"/>
    <motor joint="6" gear="1"/>
    <motor joint="7" gear="1"/>
  </actuator>
</mujoco>
